Ignoring exception in on_ready
Traceback (most recent call last):
  File "C:\Users\Maria Rairez\AppData\Local\Programs\Python\Python311\Lib\site-packages\discord\client.py", line 481, in _run_event
    await coro(*args, **kwargs)
  File "c:\Users\Maria Rairez\Desktop\TCG\main.py", line 191, in on_ready
    bot.add_view(CatalogView([]))
  File "C:\Users\Maria Rairez\AppData\Local\Programs\Python\Python311\Lib\site-packages\discord\client.py", line 3182, in add_view
    raise ValueError('View is not persistent. Items need to have a custom_id set and View must have no timeout')
ValueError: View is not persistent. Items need to have a custom_id set and View must have no timeout
Exception in /sell:
Traceback (most recent call last):
  File "c:\Users\Maria Rairez\Desktop\TCG\main.py", line 845, in sell
    card = await user_cards.find_one({"owner": user_id, "core_id": core_id})
           ^^^^^^^^^^^^^^^^^^^^^^^^^^^^^^^^^^^^^^^^^^^^^^^^^^^^^^^^^^^^^^^^^
TypeError: object NoneType can't be used in 'await' expression

Ignoring exception in command 'sell'
Traceback (most recent call last):
  File "c:\Users\Maria Rairez\Desktop\TCG\main.py", line 845, in sell
    card = await user_cards.find_one({"owner": user_id, "core_id": core_id})
           ^^^^^^^^^^^^^^^^^^^^^^^^^^^^^^^^^^^^^^^^^^^^^^^^^^^^^^^^^^^^^^^^^
TypeError: object NoneType can't be used in 'await' expression

During handling of the above exception, another exception occurred:

Traceback (most recent call last):
  File "C:\Users\Maria Rairez\AppData\Local\Programs\Python\Python311\Lib\site-packages\discord\app_commands\commands.py", line 858, in _do_call
    return await self._callback(interaction, **params)  # type: ignore
           ^^^^^^^^^^^^^^^^^^^^^^^^^^^^^^^^^^^^^^^^^^^
  File "c:\Users\Maria Rairez\Desktop\TCG\main.py", line 877, in sell
    await interaction.response.send_message(
  File "C:\Users\Maria Rairez\AppData\Local\Programs\Python\Python311\Lib\site-packages\discord\interactions.py", line 1004, in send_message
    response = await adapter.create_interaction_response(
               ^^^^^^^^^^^^^^^^^^^^^^^^^^^^^^^^^^^^^^^^^^
  File "C:\Users\Maria Rairez\AppData\Local\Programs\Python\Python311\Lib\site-packages\discord\webhook\async_.py", line 226, in request
    raise HTTPException(response, data)
discord.errors.HTTPException: 400 Bad Request (error code: 40060): Interaction has already been acknowledged.

The above exception was the direct cause of the following exception:

Traceback (most recent call last):
  File "C:\Users\Maria Rairez\AppData\Local\Programs\Python\Python311\Lib\site-packages\discord\app_commands\tree.py", line 1310, in _call
    await command._invoke_with_namespace(interaction, namespace)
  File "C:\Users\Maria Rairez\AppData\Local\Programs\Python\Python311\Lib\site-packages\discord\app_commands\commands.py", line 883, in _invoke_with_namespace
    return await self._do_call(interaction, transformed_values)
           ^^^^^^^^^^^^^^^^^^^^^^^^^^^^^^^^^^^^^^^^^^^^^^^^^^^^
  File "C:\Users\Maria Rairez\AppData\Local\Programs\Python\Python311\Lib\site-packages\discord\app_commands\commands.py", line 876, in _do_call
    raise CommandInvokeError(self, e) from e
discord.app_commands.errors.CommandInvokeError: Command 'sell' raised an exception: HTTPException: 400 Bad Request (error code: 40060): Interaction has already been acknowledged.
Exception in /sell:
Traceback (most recent call last):
  File "c:\Users\Maria Rairez\Desktop\TCG\main.py", line 845, in sell
    card = await user_cards.find_one({"owner": user_id, "core_id": core_id})
           ^^^^^^^^^^^^^^^^^^^^^^^^^^^^^^^^^^^^^^^^^^^^^^^^^^^^^^^^^^^^^^^^^
TypeError: object NoneType can't be used in 'await' expression

Ignoring exception in command 'sell'
Traceback (most recent call last):
  File "c:\Users\Maria Rairez\Desktop\TCG\main.py", line 845, in sell
    card = await user_cards.find_one({"owner": user_id, "core_id": core_id})
           ^^^^^^^^^^^^^^^^^^^^^^^^^^^^^^^^^^^^^^^^^^^^^^^^^^^^^^^^^^^^^^^^^
TypeError: object NoneType can't be used in 'await' expression

During handling of the above exception, another exception occurred:

Traceback (most recent call last):
  File "C:\Users\Maria Rairez\AppData\Local\Programs\Python\Python311\Lib\site-packages\discord\app_commands\commands.py", line 858, in _do_call
    return await self._callback(interaction, **params)  # type: ignore
           ^^^^^^^^^^^^^^^^^^^^^^^^^^^^^^^^^^^^^^^^^^^
  File "c:\Users\Maria Rairez\Desktop\TCG\main.py", line 877, in sell
    await interaction.response.send_message(
  File "C:\Users\Maria Rairez\AppData\Local\Programs\Python\Python311\Lib\site-packages\discord\interactions.py", line 1004, in send_message
    response = await adapter.create_interaction_response(
               ^^^^^^^^^^^^^^^^^^^^^^^^^^^^^^^^^^^^^^^^^^
  File "C:\Users\Maria Rairez\AppData\Local\Programs\Python\Python311\Lib\site-packages\discord\webhook\async_.py", line 226, in request
    raise HTTPException(response, data)
discord.errors.HTTPException: 400 Bad Request (error code: 40060): Interaction has already been acknowledged.

The above exception was the direct cause of the following exception:

Traceback (most recent call last):
  File "C:\Users\Maria Rairez\AppData\Local\Programs\Python\Python311\Lib\site-packages\discord\app_commands\tree.py", line 1310, in _call
    await command._invoke_with_namespace(interaction, namespace)
  File "C:\Users\Maria Rairez\AppData\Local\Programs\Python\Python311\Lib\site-packages\discord\app_commands\commands.py", line 883, in _invoke_with_namespace
    return await self._do_call(interaction, transformed_values)
           ^^^^^^^^^^^^^^^^^^^^^^^^^^^^^^^^^^^^^^^^^^^^^^^^^^^^
  File "C:\Users\Maria Rairez\AppData\Local\Programs\Python\Python311\Lib\site-packages\discord\app_commands\commands.py", line 876, in _do_call
    raise CommandInvokeError(self, e) from e
discord.app_commands.errors.CommandInvokeError: Command 'sell' raised an exception: HTTPException: 400 Bad Request (error code: 40060): Interaction has already been acknowledged.
Ignoring exception in on_ready
Traceback (most recent call last):
  File "C:\Users\Maria Rairez\AppData\Local\Programs\Python\Python311\Lib\site-packages\discord\client.py", line 481, in _run_event
    await coro(*args, **kwargs)
  File "c:\Users\Maria Rairez\Desktop\TCG\main.py", line 191, in on_ready
    bot.add_view(CatalogView([]))
  File "C:\Users\Maria Rairez\AppData\Local\Programs\Python\Python311\Lib\site-packages\discord\client.py", line 3182, in add_view
    raise ValueError('View is not persistent. Items need to have a custom_id set and View must have no timeout')
ValueError: View is not persistent. Items need to have a custom_id set and View must have no timeout
Ignoring exception in command 'collection'
Traceback (most recent call last):
  File "C:\Users\Maria Rairez\AppData\Local\Programs\Python\Python311\Lib\site-packages\discord\app_commands\commands.py", line 858, in _do_call
    return await self._callback(interaction, **params)  # type: ignore
           ^^^^^^^^^^^^^^^^^^^^^^^^^^^^^^^^^^^^^^^^^^^
  File "c:\Users\Maria Rairez\Desktop\TCG\main.py", line 628, in collection
    await interaction.response.send_message(embed=view.get_embed(), view=view, ephemeral=True)
  File "C:\Users\Maria Rairez\AppData\Local\Programs\Python\Python311\Lib\site-packages\discord\interactions.py", line 1004, in send_message
    response = await adapter.create_interaction_response(
               ^^^^^^^^^^^^^^^^^^^^^^^^^^^^^^^^^^^^^^^^^^
  File "C:\Users\Maria Rairez\AppData\Local\Programs\Python\Python311\Lib\site-packages\discord\webhook\async_.py", line 226, in request
    raise HTTPException(response, data)
discord.errors.HTTPException: 400 Bad Request (error code: 40060): Interaction has already been acknowledged.

The above exception was the direct cause of the following exception:

Traceback (most recent call last):
  File "C:\Users\Maria Rairez\AppData\Local\Programs\Python\Python311\Lib\site-packages\discord\app_commands\tree.py", line 1310, in _call
    await command._invoke_with_namespace(interaction, namespace)
  File "C:\Users\Maria Rairez\AppData\Local\Programs\Python\Python311\Lib\site-packages\discord\app_commands\commands.py", line 883, in _invoke_with_namespace
    return await self._do_call(interaction, transformed_values)
           ^^^^^^^^^^^^^^^^^^^^^^^^^^^^^^^^^^^^^^^^^^^^^^^^^^^^
  File "C:\Users\Maria Rairez\AppData\Local\Programs\Python\Python311\Lib\site-packages\discord\app_commands\commands.py", line 876, in _do_call
    raise CommandInvokeError(self, e) from e
discord.app_commands.errors.CommandInvokeError: Command 'collection' raised an exception: HTTPException: 400 Bad Request (error code: 40060): Interaction has already been acknowledged.
Ignoring exception in command 'collection'
Traceback (most recent call last):
  File "C:\Users\Maria Rairez\AppData\Local\Programs\Python\Python311\Lib\site-packages\discord\app_commands\commands.py", line 858, in _do_call
    return await self._callback(interaction, **params)  # type: ignore
           ^^^^^^^^^^^^^^^^^^^^^^^^^^^^^^^^^^^^^^^^^^^
  File "c:\Users\Maria Rairez\Desktop\TCG\main.py", line 628, in collection
    await interaction.response.send_message(embed=view.get_embed(), view=view, ephemeral=True)
  File "C:\Users\Maria Rairez\AppData\Local\Programs\Python\Python311\Lib\site-packages\discord\interactions.py", line 1004, in send_message
    response = await adapter.create_interaction_response(
               ^^^^^^^^^^^^^^^^^^^^^^^^^^^^^^^^^^^^^^^^^^
  File "C:\Users\Maria Rairez\AppData\Local\Programs\Python\Python311\Lib\site-packages\discord\webhook\async_.py", line 226, in request
    raise HTTPException(response, data)
discord.errors.HTTPException: 400 Bad Request (error code: 40060): Interaction has already been acknowledged.

The above exception was the direct cause of the following exception:

Traceback (most recent call last):
  File "C:\Users\Maria Rairez\AppData\Local\Programs\Python\Python311\Lib\site-packages\discord\app_commands\tree.py", line 1310, in _call
    await command._invoke_with_namespace(interaction, namespace)
  File "C:\Users\Maria Rairez\AppData\Local\Programs\Python\Python311\Lib\site-packages\discord\app_commands\commands.py", line 883, in _invoke_with_namespace
    return await self._do_call(interaction, transformed_values)
           ^^^^^^^^^^^^^^^^^^^^^^^^^^^^^^^^^^^^^^^^^^^^^^^^^^^^
  File "C:\Users\Maria Rairez\AppData\Local\Programs\Python\Python311\Lib\site-packages\discord\app_commands\commands.py", line 876, in _do_call
    raise CommandInvokeError(self, e) from e
discord.app_commands.errors.CommandInvokeError: Command 'collection' raised an exception: HTTPException: 400 Bad Request (error code: 40060): Interaction has already been acknowledged.
Ignoring exception in command 'sell'
Traceback (most recent call last):
  File "C:\Users\Maria Rairez\AppData\Local\Programs\Python\Python311\Lib\site-packages\discord\app_commands\commands.py", line 858, in _do_call
    return await self._callback(interaction, **params)  # type: ignore
           ^^^^^^^^^^^^^^^^^^^^^^^^^^^^^^^^^^^^^^^^^^^
  File "c:\Users\Maria Rairez\Desktop\TCG\main.py", line 858, in sell
    if str(card_id) in map(str, team_data["team"].get(zone, [])):
                                ^^^^^^^^^^^^^^^^^^^^^
AttributeError: 'list' object has no attribute 'get'

The above exception was the direct cause of the following exception:

Traceback (most recent call last):
  File "C:\Users\Maria Rairez\AppData\Local\Programs\Python\Python311\Lib\site-packages\discord\app_commands\tree.py", line 1310, in _call
    await command._invoke_with_namespace(interaction, namespace)
  File "C:\Users\Maria Rairez\AppData\Local\Programs\Python\Python311\Lib\site-packages\discord\app_commands\commands.py", line 883, in _invoke_with_namespace
    return await self._do_call(interaction, transformed_values)
           ^^^^^^^^^^^^^^^^^^^^^^^^^^^^^^^^^^^^^^^^^^^^^^^^^^^^
  File "C:\Users\Maria Rairez\AppData\Local\Programs\Python\Python311\Lib\site-packages\discord\app_commands\commands.py", line 876, in _do_call
    raise CommandInvokeError(self, e) from e
discord.app_commands.errors.CommandInvokeError: Command 'sell' raised an exception: AttributeError: 'list' object has no attribute 'get'
Ignoring exception in command 'sell'
Traceback (most recent call last):
  File "C:\Users\Maria Rairez\AppData\Local\Programs\Python\Python311\Lib\site-packages\discord\app_commands\commands.py", line 858, in _do_call
    return await self._callback(interaction, **params)  # type: ignore
           ^^^^^^^^^^^^^^^^^^^^^^^^^^^^^^^^^^^^^^^^^^^
  File "c:\Users\Maria Rairez\Desktop\TCG\main.py", line 858, in sell
    if str(card_id) in map(str, team_data["team"].get(zone, [])):
                                ^^^^^^^^^^^^^^^^^^^^^
AttributeError: 'list' object has no attribute 'get'

The above exception was the direct cause of the following exception:

Traceback (most recent call last):
  File "C:\Users\Maria Rairez\AppData\Local\Programs\Python\Python311\Lib\site-packages\discord\app_commands\tree.py", line 1310, in _call
    await command._invoke_with_namespace(interaction, namespace)
  File "C:\Users\Maria Rairez\AppData\Local\Programs\Python\Python311\Lib\site-packages\discord\app_commands\commands.py", line 883, in _invoke_with_namespace
    return await self._do_call(interaction, transformed_values)
           ^^^^^^^^^^^^^^^^^^^^^^^^^^^^^^^^^^^^^^^^^^^^^^^^^^^^
  File "C:\Users\Maria Rairez\AppData\Local\Programs\Python\Python311\Lib\site-packages\discord\app_commands\commands.py", line 876, in _do_call
    raise CommandInvokeError(self, e) from e
discord.app_commands.errors.CommandInvokeError: Command 'sell' raised an exception: AttributeError: 'list' object has no attribute 'get'
Ignoring exception in command 'collection'
Traceback (most recent call last):
  File "C:\Users\Maria Rairez\AppData\Local\Programs\Python\Python311\Lib\site-packages\discord\app_commands\commands.py", line 858, in _do_call
    return await self._callback(interaction, **params)  # type: ignore
           ^^^^^^^^^^^^^^^^^^^^^^^^^^^^^^^^^^^^^^^^^^^
  File "c:\Users\Maria Rairez\Desktop\TCG\main.py", line 628, in collection
    await interaction.response.send_message(embed=view.get_embed(), view=view, ephemeral=True)
  File "C:\Users\Maria Rairez\AppData\Local\Programs\Python\Python311\Lib\site-packages\discord\interactions.py", line 1004, in send_message
    response = await adapter.create_interaction_response(
               ^^^^^^^^^^^^^^^^^^^^^^^^^^^^^^^^^^^^^^^^^^
  File "C:\Users\Maria Rairez\AppData\Local\Programs\Python\Python311\Lib\site-packages\discord\webhook\async_.py", line 226, in request
    raise HTTPException(response, data)
discord.errors.HTTPException: 400 Bad Request (error code: 40060): Interaction has already been acknowledged.

The above exception was the direct cause of the following exception:

Traceback (most recent call last):
  File "C:\Users\Maria Rairez\AppData\Local\Programs\Python\Python311\Lib\site-packages\discord\app_commands\tree.py", line 1310, in _call
    await command._invoke_with_namespace(interaction, namespace)
  File "C:\Users\Maria Rairez\AppData\Local\Programs\Python\Python311\Lib\site-packages\discord\app_commands\commands.py", line 883, in _invoke_with_namespace
    return await self._do_call(interaction, transformed_values)
           ^^^^^^^^^^^^^^^^^^^^^^^^^^^^^^^^^^^^^^^^^^^^^^^^^^^^
  File "C:\Users\Maria Rairez\AppData\Local\Programs\Python\Python311\Lib\site-packages\discord\app_commands\commands.py", line 876, in _do_call
    raise CommandInvokeError(self, e) from e
discord.app_commands.errors.CommandInvokeError: Command 'collection' raised an exception: HTTPException: 400 Bad Request (error code: 40060): Interaction has already been acknowledged.
Ignoring exception in command 'sell'
Traceback (most recent call last):
  File "C:\Users\Maria Rairez\AppData\Local\Programs\Python\Python311\Lib\site-packages\discord\app_commands\commands.py", line 858, in _do_call
    return await self._callback(interaction, **params)  # type: ignore
           ^^^^^^^^^^^^^^^^^^^^^^^^^^^^^^^^^^^^^^^^^^^
  File "c:\Users\Maria Rairez\Desktop\TCG\main.py", line 858, in sell
    if str(card_id) in map(str, team_data["team"].get(zone, [])):
                                ^^^^^^^^^^^^^^^^^^^^^
AttributeError: 'list' object has no attribute 'get'

The above exception was the direct cause of the following exception:

Traceback (most recent call last):
  File "C:\Users\Maria Rairez\AppData\Local\Programs\Python\Python311\Lib\site-packages\discord\app_commands\tree.py", line 1310, in _call
    await command._invoke_with_namespace(interaction, namespace)
  File "C:\Users\Maria Rairez\AppData\Local\Programs\Python\Python311\Lib\site-packages\discord\app_commands\commands.py", line 883, in _invoke_with_namespace
    return await self._do_call(interaction, transformed_values)
           ^^^^^^^^^^^^^^^^^^^^^^^^^^^^^^^^^^^^^^^^^^^^^^^^^^^^
  File "C:\Users\Maria Rairez\AppData\Local\Programs\Python\Python311\Lib\site-packages\discord\app_commands\commands.py", line 876, in _do_call
    raise CommandInvokeError(self, e) from e
discord.app_commands.errors.CommandInvokeError: Command 'sell' raised an exception: AttributeError: 'list' object has no attribute 'get'
Ignoring exception in command 'sell'
Traceback (most recent call last):
  File "C:\Users\Maria Rairez\AppData\Local\Programs\Python\Python311\Lib\site-packages\discord\app_commands\commands.py", line 858, in _do_call
    return await self._callback(interaction, **params)  # type: ignore
           ^^^^^^^^^^^^^^^^^^^^^^^^^^^^^^^^^^^^^^^^^^^
  File "c:\Users\Maria Rairez\Desktop\TCG\main.py", line 858, in sell
    if str(card_id) in map(str, team_data["team"].get(zone, [])):
                                ^^^^^^^^^^^^^^^^^^^^^
AttributeError: 'list' object has no attribute 'get'

The above exception was the direct cause of the following exception:

Traceback (most recent call last):
  File "C:\Users\Maria Rairez\AppData\Local\Programs\Python\Python311\Lib\site-packages\discord\app_commands\tree.py", line 1310, in _call
    await command._invoke_with_namespace(interaction, namespace)
  File "C:\Users\Maria Rairez\AppData\Local\Programs\Python\Python311\Lib\site-packages\discord\app_commands\commands.py", line 883, in _invoke_with_namespace
    return await self._do_call(interaction, transformed_values)
           ^^^^^^^^^^^^^^^^^^^^^^^^^^^^^^^^^^^^^^^^^^^^^^^^^^^^
  File "C:\Users\Maria Rairez\AppData\Local\Programs\Python\Python311\Lib\site-packages\discord\app_commands\commands.py", line 876, in _do_call
    raise CommandInvokeError(self, e) from e
discord.app_commands.errors.CommandInvokeError: Command 'sell' raised an exception: AttributeError: 'list' object has no attribute 'get'
Ignoring exception in on_ready
Traceback (most recent call last):
  File "C:\Users\Maria Rairez\AppData\Local\Programs\Python\Python311\Lib\site-packages\discord\client.py", line 481, in _run_event
    await coro(*args, **kwargs)
  File "c:\Users\Maria Rairez\Desktop\TCG\main.py", line 191, in on_ready
    bot.add_view(CatalogView([]))
  File "C:\Users\Maria Rairez\AppData\Local\Programs\Python\Python311\Lib\site-packages\discord\client.py", line 3182, in add_view
    raise ValueError('View is not persistent. Items need to have a custom_id set and View must have no timeout')
ValueError: View is not persistent. Items need to have a custom_id set and View must have no timeout
Ignoring exception in command 'sell'
Traceback (most recent call last):
  File "C:\Users\Maria Rairez\AppData\Local\Programs\Python\Python311\Lib\site-packages\discord\app_commands\commands.py", line 858, in _do_call
    return await self._callback(interaction, **params)  # type: ignore
           ^^^^^^^^^^^^^^^^^^^^^^^^^^^^^^^^^^^^^^^^^^^
  File "c:\Users\Maria Rairez\Desktop\TCG\main.py", line 852, in sell
    return await interaction.response.send_message("❌ No card with that ID was found in your collection.", ephemeral=True)
           ^^^^^^^^^^^^^^^^^^^^^^^^^^^^^^^^^^^^^^^^^^^^^^^^^^^^^^^^^^^^^^^^^^^^^^^^^^^^^^^^^^^^^^^^^^^^^^^^^^^^^^^^^^^^^^^
  File "C:\Users\Maria Rairez\AppData\Local\Programs\Python\Python311\Lib\site-packages\discord\interactions.py", line 1004, in send_message
    response = await adapter.create_interaction_response(
               ^^^^^^^^^^^^^^^^^^^^^^^^^^^^^^^^^^^^^^^^^^
  File "C:\Users\Maria Rairez\AppData\Local\Programs\Python\Python311\Lib\site-packages\discord\webhook\async_.py", line 224, in request
    raise NotFound(response, data)
discord.errors.NotFound: 404 Not Found (error code: 10062): Unknown interaction

The above exception was the direct cause of the following exception:

Traceback (most recent call last):
  File "C:\Users\Maria Rairez\AppData\Local\Programs\Python\Python311\Lib\site-packages\discord\app_commands\tree.py", line 1310, in _call
    await command._invoke_with_namespace(interaction, namespace)
  File "C:\Users\Maria Rairez\AppData\Local\Programs\Python\Python311\Lib\site-packages\discord\app_commands\commands.py", line 883, in _invoke_with_namespace
    return await self._do_call(interaction, transformed_values)
           ^^^^^^^^^^^^^^^^^^^^^^^^^^^^^^^^^^^^^^^^^^^^^^^^^^^^
  File "C:\Users\Maria Rairez\AppData\Local\Programs\Python\Python311\Lib\site-packages\discord\app_commands\commands.py", line 876, in _do_call
    raise CommandInvokeError(self, e) from e
discord.app_commands.errors.CommandInvokeError: Command 'sell' raised an exception: NotFound: 404 Not Found (error code: 10062): Unknown interaction
Ignoring exception in on_ready
Traceback (most recent call last):
  File "C:\Users\Maria Rairez\AppData\Local\Programs\Python\Python311\Lib\site-packages\discord\client.py", line 481, in _run_event
    await coro(*args, **kwargs)
  File "c:\Users\Maria Rairez\Desktop\TCG\main.py", line 191, in on_ready
    bot.add_view(CatalogView([]))
  File "C:\Users\Maria Rairez\AppData\Local\Programs\Python\Python311\Lib\site-packages\discord\client.py", line 3182, in add_view
    raise ValueError('View is not persistent. Items need to have a custom_id set and View must have no timeout')
ValueError: View is not persistent. Items need to have a custom_id set and View must have no timeout
Ignoring exception in command 'duel'
Traceback (most recent call last):
  File "C:\Users\Maria Rairez\AppData\Local\Programs\Python\Python311\Lib\site-packages\discord\app_commands\commands.py", line 858, in _do_call
    return await self._callback(interaction, **params)  # type: ignore
           ^^^^^^^^^^^^^^^^^^^^^^^^^^^^^^^^^^^^^^^^^^^
  File "c:\Users\Maria Rairez\Desktop\TCG\main.py", line 1560, in duel
    await interaction.response.defer()
  File "C:\Users\Maria Rairez\AppData\Local\Programs\Python\Python311\Lib\site-packages\discord\interactions.py", line 844, in defer
    response = await adapter.create_interaction_response(
               ^^^^^^^^^^^^^^^^^^^^^^^^^^^^^^^^^^^^^^^^^^
  File "C:\Users\Maria Rairez\AppData\Local\Programs\Python\Python311\Lib\site-packages\discord\webhook\async_.py", line 226, in request
    raise HTTPException(response, data)
discord.errors.HTTPException: 400 Bad Request (error code: 40060): Interaction has already been acknowledged.

The above exception was the direct cause of the following exception:

Traceback (most recent call last):
  File "C:\Users\Maria Rairez\AppData\Local\Programs\Python\Python311\Lib\site-packages\discord\app_commands\tree.py", line 1310, in _call
    await command._invoke_with_namespace(interaction, namespace)
  File "C:\Users\Maria Rairez\AppData\Local\Programs\Python\Python311\Lib\site-packages\discord\app_commands\commands.py", line 883, in _invoke_with_namespace
    return await self._do_call(interaction, transformed_values)
           ^^^^^^^^^^^^^^^^^^^^^^^^^^^^^^^^^^^^^^^^^^^^^^^^^^^^
  File "C:\Users\Maria Rairez\AppData\Local\Programs\Python\Python311\Lib\site-packages\discord\app_commands\commands.py", line 876, in _do_call
    raise CommandInvokeError(self, e) from e
discord.app_commands.errors.CommandInvokeError: Command 'duel' raised an exception: HTTPException: 400 Bad Request (error code: 40060): Interaction has already been acknowledged.
Ignoring exception in command 'duel'
Traceback (most recent call last):
  File "C:\Users\Maria Rairez\AppData\Local\Programs\Python\Python311\Lib\site-packages\discord\app_commands\commands.py", line 858, in _do_call
    return await self._callback(interaction, **params)  # type: ignore
           ^^^^^^^^^^^^^^^^^^^^^^^^^^^^^^^^^^^^^^^^^^^
  File "c:\Users\Maria Rairez\Desktop\TCG\main.py", line 1560, in duel
    await interaction.response.defer()
  File "C:\Users\Maria Rairez\AppData\Local\Programs\Python\Python311\Lib\site-packages\discord\interactions.py", line 844, in defer
    response = await adapter.create_interaction_response(
               ^^^^^^^^^^^^^^^^^^^^^^^^^^^^^^^^^^^^^^^^^^
  File "C:\Users\Maria Rairez\AppData\Local\Programs\Python\Python311\Lib\site-packages\discord\webhook\async_.py", line 224, in request
    raise NotFound(response, data)
discord.errors.NotFound: 404 Not Found (error code: 10062): Unknown interaction

The above exception was the direct cause of the following exception:

Traceback (most recent call last):
  File "C:\Users\Maria Rairez\AppData\Local\Programs\Python\Python311\Lib\site-packages\discord\app_commands\tree.py", line 1310, in _call
    await command._invoke_with_namespace(interaction, namespace)
  File "C:\Users\Maria Rairez\AppData\Local\Programs\Python\Python311\Lib\site-packages\discord\app_commands\commands.py", line 883, in _invoke_with_namespace
    return await self._do_call(interaction, transformed_values)
           ^^^^^^^^^^^^^^^^^^^^^^^^^^^^^^^^^^^^^^^^^^^^^^^^^^^^
  File "C:\Users\Maria Rairez\AppData\Local\Programs\Python\Python311\Lib\site-packages\discord\app_commands\commands.py", line 876, in _do_call
    raise CommandInvokeError(self, e) from e
discord.app_commands.errors.CommandInvokeError: Command 'duel' raised an exception: NotFound: 404 Not Found (error code: 10062): Unknown interaction
Ignoring exception in command 'duel'
Traceback (most recent call last):
  File "C:\Users\Maria Rairez\AppData\Local\Programs\Python\Python311\Lib\site-packages\discord\app_commands\commands.py", line 858, in _do_call
    return await self._callback(interaction, **params)  # type: ignore
           ^^^^^^^^^^^^^^^^^^^^^^^^^^^^^^^^^^^^^^^^^^^
  File "c:\Users\Maria Rairez\Desktop\TCG\main.py", line 1560, in duel
    await interaction.response.defer()
  File "C:\Users\Maria Rairez\AppData\Local\Programs\Python\Python311\Lib\site-packages\discord\interactions.py", line 844, in defer
    response = await adapter.create_interaction_response(
               ^^^^^^^^^^^^^^^^^^^^^^^^^^^^^^^^^^^^^^^^^^
  File "C:\Users\Maria Rairez\AppData\Local\Programs\Python\Python311\Lib\site-packages\discord\webhook\async_.py", line 224, in request
    raise NotFound(response, data)
discord.errors.NotFound: 404 Not Found (error code: 10062): Unknown interaction

The above exception was the direct cause of the following exception:

Traceback (most recent call last):
  File "C:\Users\Maria Rairez\AppData\Local\Programs\Python\Python311\Lib\site-packages\discord\app_commands\tree.py", line 1310, in _call
    await command._invoke_with_namespace(interaction, namespace)
  File "C:\Users\Maria Rairez\AppData\Local\Programs\Python\Python311\Lib\site-packages\discord\app_commands\commands.py", line 883, in _invoke_with_namespace
    return await self._do_call(interaction, transformed_values)
           ^^^^^^^^^^^^^^^^^^^^^^^^^^^^^^^^^^^^^^^^^^^^^^^^^^^^
  File "C:\Users\Maria Rairez\AppData\Local\Programs\Python\Python311\Lib\site-packages\discord\app_commands\commands.py", line 876, in _do_call
    raise CommandInvokeError(self, e) from e
discord.app_commands.errors.CommandInvokeError: Command 'duel' raised an exception: NotFound: 404 Not Found (error code: 10062): Unknown interaction
Ignoring exception in command 'profile'
Traceback (most recent call last):
  File "C:\Users\Maria Rairez\AppData\Local\Programs\Python\Python311\Lib\site-packages\discord\app_commands\commands.py", line 858, in _do_call
    return await self._callback(interaction, **params)  # type: ignore
           ^^^^^^^^^^^^^^^^^^^^^^^^^^^^^^^^^^^^^^^^^^^
  File "c:\Users\Maria Rairez\Desktop\TCG\main.py", line 232, in profile
    await interaction.response.send_message(embed=embed)
  File "C:\Users\Maria Rairez\AppData\Local\Programs\Python\Python311\Lib\site-packages\discord\interactions.py", line 1004, in send_message
    response = await adapter.create_interaction_response(
               ^^^^^^^^^^^^^^^^^^^^^^^^^^^^^^^^^^^^^^^^^^
  File "C:\Users\Maria Rairez\AppData\Local\Programs\Python\Python311\Lib\site-packages\discord\webhook\async_.py", line 226, in request
    raise HTTPException(response, data)
discord.errors.HTTPException: 400 Bad Request (error code: 40060): Interaction has already been acknowledged.

The above exception was the direct cause of the following exception:

Traceback (most recent call last):
  File "C:\Users\Maria Rairez\AppData\Local\Programs\Python\Python311\Lib\site-packages\discord\app_commands\tree.py", line 1310, in _call
    await command._invoke_with_namespace(interaction, namespace)
  File "C:\Users\Maria Rairez\AppData\Local\Programs\Python\Python311\Lib\site-packages\discord\app_commands\commands.py", line 883, in _invoke_with_namespace
    return await self._do_call(interaction, transformed_values)
           ^^^^^^^^^^^^^^^^^^^^^^^^^^^^^^^^^^^^^^^^^^^^^^^^^^^^
  File "C:\Users\Maria Rairez\AppData\Local\Programs\Python\Python311\Lib\site-packages\discord\app_commands\commands.py", line 876, in _do_call
    raise CommandInvokeError(self, e) from e
discord.app_commands.errors.CommandInvokeError: Command 'profile' raised an exception: HTTPException: 400 Bad Request (error code: 40060): Interaction has already been acknowledged.
Ignoring exception in command 'duel'
Traceback (most recent call last):
  File "C:\Users\Maria Rairez\AppData\Local\Programs\Python\Python311\Lib\site-packages\discord\app_commands\commands.py", line 858, in _do_call
    return await self._callback(interaction, **params)  # type: ignore
           ^^^^^^^^^^^^^^^^^^^^^^^^^^^^^^^^^^^^^^^^^^^
  File "c:\Users\Maria Rairez\Desktop\TCG\main.py", line 1560, in duel
    await interaction.response.defer()
  File "C:\Users\Maria Rairez\AppData\Local\Programs\Python\Python311\Lib\site-packages\discord\interactions.py", line 844, in defer
    response = await adapter.create_interaction_response(
               ^^^^^^^^^^^^^^^^^^^^^^^^^^^^^^^^^^^^^^^^^^
  File "C:\Users\Maria Rairez\AppData\Local\Programs\Python\Python311\Lib\site-packages\discord\webhook\async_.py", line 224, in request
    raise NotFound(response, data)
discord.errors.NotFound: 404 Not Found (error code: 10062): Unknown interaction

The above exception was the direct cause of the following exception:

Traceback (most recent call last):
  File "C:\Users\Maria Rairez\AppData\Local\Programs\Python\Python311\Lib\site-packages\discord\app_commands\tree.py", line 1310, in _call
    await command._invoke_with_namespace(interaction, namespace)
  File "C:\Users\Maria Rairez\AppData\Local\Programs\Python\Python311\Lib\site-packages\discord\app_commands\commands.py", line 883, in _invoke_with_namespace
    return await self._do_call(interaction, transformed_values)
           ^^^^^^^^^^^^^^^^^^^^^^^^^^^^^^^^^^^^^^^^^^^^^^^^^^^^
  File "C:\Users\Maria Rairez\AppData\Local\Programs\Python\Python311\Lib\site-packages\discord\app_commands\commands.py", line 876, in _do_call
    raise CommandInvokeError(self, e) from e
discord.app_commands.errors.CommandInvokeError: Command 'duel' raised an exception: NotFound: 404 Not Found (error code: 10062): Unknown interaction
Ignoring exception in command 'duel'
Traceback (most recent call last):
  File "C:\Users\Maria Rairez\AppData\Local\Programs\Python\Python311\Lib\site-packages\discord\app_commands\commands.py", line 858, in _do_call
    return await self._callback(interaction, **params)  # type: ignore
           ^^^^^^^^^^^^^^^^^^^^^^^^^^^^^^^^^^^^^^^^^^^
  File "c:\Users\Maria Rairez\Desktop\TCG\main.py", line 1560, in duel
    await interaction.response.defer()
  File "C:\Users\Maria Rairez\AppData\Local\Programs\Python\Python311\Lib\site-packages\discord\interactions.py", line 844, in defer
    response = await adapter.create_interaction_response(
               ^^^^^^^^^^^^^^^^^^^^^^^^^^^^^^^^^^^^^^^^^^
  File "C:\Users\Maria Rairez\AppData\Local\Programs\Python\Python311\Lib\site-packages\discord\webhook\async_.py", line 226, in request
    raise HTTPException(response, data)
discord.errors.HTTPException: 400 Bad Request (error code: 40060): Interaction has already been acknowledged.

The above exception was the direct cause of the following exception:

Traceback (most recent call last):
  File "C:\Users\Maria Rairez\AppData\Local\Programs\Python\Python311\Lib\site-packages\discord\app_commands\tree.py", line 1310, in _call
    await command._invoke_with_namespace(interaction, namespace)
  File "C:\Users\Maria Rairez\AppData\Local\Programs\Python\Python311\Lib\site-packages\discord\app_commands\commands.py", line 883, in _invoke_with_namespace
    return await self._do_call(interaction, transformed_values)
           ^^^^^^^^^^^^^^^^^^^^^^^^^^^^^^^^^^^^^^^^^^^^^^^^^^^^
  File "C:\Users\Maria Rairez\AppData\Local\Programs\Python\Python311\Lib\site-packages\discord\app_commands\commands.py", line 876, in _do_call
    raise CommandInvokeError(self, e) from e
discord.app_commands.errors.CommandInvokeError: Command 'duel' raised an exception: HTTPException: 400 Bad Request (error code: 40060): Interaction has already been acknowledged.
Ignoring exception in on_ready
Traceback (most recent call last):
  File "C:\Users\Maria Rairez\AppData\Local\Programs\Python\Python311\Lib\site-packages\discord\client.py", line 481, in _run_event
    await coro(*args, **kwargs)
  File "c:\Users\Maria Rairez\Desktop\TCG\main.py", line 191, in on_ready
    bot.add_view(CatalogView([]))
  File "C:\Users\Maria Rairez\AppData\Local\Programs\Python\Python311\Lib\site-packages\discord\client.py", line 3182, in add_view
    raise ValueError('View is not persistent. Items need to have a custom_id set and View must have no timeout')
ValueError: View is not persistent. Items need to have a custom_id set and View must have no timeout
Ignoring exception in on_ready
Traceback (most recent call last):
  File "C:\Users\Maria Rairez\AppData\Local\Programs\Python\Python311\Lib\site-packages\discord\client.py", line 481, in _run_event
    await coro(*args, **kwargs)
  File "c:\Users\Maria Rairez\Desktop\TCG\main.py", line 191, in on_ready
    bot.add_view(CatalogView([]))
  File "C:\Users\Maria Rairez\AppData\Local\Programs\Python\Python311\Lib\site-packages\discord\client.py", line 3182, in add_view
    raise ValueError('View is not persistent. Items need to have a custom_id set and View must have no timeout')
ValueError: View is not persistent. Items need to have a custom_id set and View must have no timeout
Ignoring exception in command 'duel'
Traceback (most recent call last):
  File "C:\Users\Maria Rairez\AppData\Local\Programs\Python\Python311\Lib\site-packages\discord\app_commands\commands.py", line 858, in _do_call
    return await self._callback(interaction, **params)  # type: ignore
           ^^^^^^^^^^^^^^^^^^^^^^^^^^^^^^^^^^^^^^^^^^^
  File "c:\Users\Maria Rairez\Desktop\TCG\main.py", line 1560, in duel
    await interaction.response.defer()
  File "C:\Users\Maria Rairez\AppData\Local\Programs\Python\Python311\Lib\site-packages\discord\interactions.py", line 844, in defer
    response = await adapter.create_interaction_response(
               ^^^^^^^^^^^^^^^^^^^^^^^^^^^^^^^^^^^^^^^^^^
  File "C:\Users\Maria Rairez\AppData\Local\Programs\Python\Python311\Lib\site-packages\discord\webhook\async_.py", line 226, in request
    raise HTTPException(response, data)
discord.errors.HTTPException: 400 Bad Request (error code: 40060): Interaction has already been acknowledged.

The above exception was the direct cause of the following exception:

Traceback (most recent call last):
  File "C:\Users\Maria Rairez\AppData\Local\Programs\Python\Python311\Lib\site-packages\discord\app_commands\tree.py", line 1310, in _call
    await command._invoke_with_namespace(interaction, namespace)
  File "C:\Users\Maria Rairez\AppData\Local\Programs\Python\Python311\Lib\site-packages\discord\app_commands\commands.py", line 883, in _invoke_with_namespace
    return await self._do_call(interaction, transformed_values)
           ^^^^^^^^^^^^^^^^^^^^^^^^^^^^^^^^^^^^^^^^^^^^^^^^^^^^
  File "C:\Users\Maria Rairez\AppData\Local\Programs\Python\Python311\Lib\site-packages\discord\app_commands\commands.py", line 876, in _do_call
    raise CommandInvokeError(self, e) from e
discord.app_commands.errors.CommandInvokeError: Command 'duel' raised an exception: HTTPException: 400 Bad Request (error code: 40060): Interaction has already been acknowledged.
Ignoring exception in command 'duel'
Traceback (most recent call last):
  File "C:\Users\Maria Rairez\AppData\Local\Programs\Python\Python311\Lib\site-packages\discord\app_commands\commands.py", line 858, in _do_call
    return await self._callback(interaction, **params)  # type: ignore
           ^^^^^^^^^^^^^^^^^^^^^^^^^^^^^^^^^^^^^^^^^^^
  File "c:\Users\Maria Rairez\Desktop\TCG\main.py", line 1560, in duel
    await interaction.response.defer()
  File "C:\Users\Maria Rairez\AppData\Local\Programs\Python\Python311\Lib\site-packages\discord\interactions.py", line 844, in defer
    response = await adapter.create_interaction_response(
               ^^^^^^^^^^^^^^^^^^^^^^^^^^^^^^^^^^^^^^^^^^
  File "C:\Users\Maria Rairez\AppData\Local\Programs\Python\Python311\Lib\site-packages\discord\webhook\async_.py", line 224, in request
    raise NotFound(response, data)
discord.errors.NotFound: 404 Not Found (error code: 10062): Unknown interaction

The above exception was the direct cause of the following exception:

Traceback (most recent call last):
  File "C:\Users\Maria Rairez\AppData\Local\Programs\Python\Python311\Lib\site-packages\discord\app_commands\tree.py", line 1310, in _call
    await command._invoke_with_namespace(interaction, namespace)
  File "C:\Users\Maria Rairez\AppData\Local\Programs\Python\Python311\Lib\site-packages\discord\app_commands\commands.py", line 883, in _invoke_with_namespace
    return await self._do_call(interaction, transformed_values)
           ^^^^^^^^^^^^^^^^^^^^^^^^^^^^^^^^^^^^^^^^^^^^^^^^^^^^
  File "C:\Users\Maria Rairez\AppData\Local\Programs\Python\Python311\Lib\site-packages\discord\app_commands\commands.py", line 876, in _do_call
    raise CommandInvokeError(self, e) from e
discord.app_commands.errors.CommandInvokeError: Command 'duel' raised an exception: NotFound: 404 Not Found (error code: 10062): Unknown interaction
Ignoring exception in on_ready
Traceback (most recent call last):
  File "C:\Users\Maria Rairez\AppData\Local\Programs\Python\Python311\Lib\site-packages\discord\client.py", line 481, in _run_event
    await coro(*args, **kwargs)
  File "c:\Users\Maria Rairez\Desktop\TCG\main.py", line 191, in on_ready
    bot.add_view(CatalogView([]))
  File "C:\Users\Maria Rairez\AppData\Local\Programs\Python\Python311\Lib\site-packages\discord\client.py", line 3182, in add_view
    raise ValueError('View is not persistent. Items need to have a custom_id set and View must have no timeout')
ValueError: View is not persistent. Items need to have a custom_id set and View must have no timeout
Ignoring exception in command 'duel'
Traceback (most recent call last):
  File "C:\Users\Maria Rairez\AppData\Local\Programs\Python\Python311\Lib\site-packages\discord\app_commands\commands.py", line 858, in _do_call
    return await self._callback(interaction, **params)  # type: ignore
           ^^^^^^^^^^^^^^^^^^^^^^^^^^^^^^^^^^^^^^^^^^^
  File "c:\Users\Maria Rairez\Desktop\TCG\main.py", line 1560, in duel
    await interaction.response.defer()
  File "C:\Users\Maria Rairez\AppData\Local\Programs\Python\Python311\Lib\site-packages\discord\interactions.py", line 844, in defer
    response = await adapter.create_interaction_response(
               ^^^^^^^^^^^^^^^^^^^^^^^^^^^^^^^^^^^^^^^^^^
  File "C:\Users\Maria Rairez\AppData\Local\Programs\Python\Python311\Lib\site-packages\discord\webhook\async_.py", line 226, in request
    raise HTTPException(response, data)
discord.errors.HTTPException: 400 Bad Request (error code: 40060): Interaction has already been acknowledged.

The above exception was the direct cause of the following exception:

Traceback (most recent call last):
  File "C:\Users\Maria Rairez\AppData\Local\Programs\Python\Python311\Lib\site-packages\discord\app_commands\tree.py", line 1310, in _call
    await command._invoke_with_namespace(interaction, namespace)
  File "C:\Users\Maria Rairez\AppData\Local\Programs\Python\Python311\Lib\site-packages\discord\app_commands\commands.py", line 883, in _invoke_with_namespace
    return await self._do_call(interaction, transformed_values)
           ^^^^^^^^^^^^^^^^^^^^^^^^^^^^^^^^^^^^^^^^^^^^^^^^^^^^
  File "C:\Users\Maria Rairez\AppData\Local\Programs\Python\Python311\Lib\site-packages\discord\app_commands\commands.py", line 876, in _do_call
    raise CommandInvokeError(self, e) from e
discord.app_commands.errors.CommandInvokeError: Command 'duel' raised an exception: HTTPException: 400 Bad Request (error code: 40060): Interaction has already been acknowledged.
Ignoring exception in on_ready
Traceback (most recent call last):
  File "C:\Users\Maria Rairez\AppData\Local\Programs\Python\Python311\Lib\site-packages\discord\client.py", line 481, in _run_event
    await coro(*args, **kwargs)
  File "c:\Users\Maria Rairez\Desktop\TCG\main.py", line 190, in on_ready
    bot.add_view(CatalogView([]))
  File "C:\Users\Maria Rairez\AppData\Local\Programs\Python\Python311\Lib\site-packages\discord\client.py", line 3182, in add_view
    raise ValueError('View is not persistent. Items need to have a custom_id set and View must have no timeout')
ValueError: View is not persistent. Items need to have a custom_id set and View must have no timeout
Ignoring exception in command 'duel'
Traceback (most recent call last):
  File "C:\Users\Maria Rairez\AppData\Local\Programs\Python\Python311\Lib\site-packages\discord\app_commands\commands.py", line 858, in _do_call
    return await self._callback(interaction, **params)  # type: ignore
           ^^^^^^^^^^^^^^^^^^^^^^^^^^^^^^^^^^^^^^^^^^^
  File "c:\Users\Maria Rairez\Desktop\TCG\main.py", line 1566, in duel
    await interaction.response.defer(ephemeral=False)
  File "C:\Users\Maria Rairez\AppData\Local\Programs\Python\Python311\Lib\site-packages\discord\interactions.py", line 844, in defer
    response = await adapter.create_interaction_response(
               ^^^^^^^^^^^^^^^^^^^^^^^^^^^^^^^^^^^^^^^^^^
  File "C:\Users\Maria Rairez\AppData\Local\Programs\Python\Python311\Lib\site-packages\discord\webhook\async_.py", line 226, in request
    raise HTTPException(response, data)
discord.errors.HTTPException: 400 Bad Request (error code: 40060): Interaction has already been acknowledged.

The above exception was the direct cause of the following exception:

Traceback (most recent call last):
  File "C:\Users\Maria Rairez\AppData\Local\Programs\Python\Python311\Lib\site-packages\discord\app_commands\tree.py", line 1310, in _call
    await command._invoke_with_namespace(interaction, namespace)
  File "C:\Users\Maria Rairez\AppData\Local\Programs\Python\Python311\Lib\site-packages\discord\app_commands\commands.py", line 883, in _invoke_with_namespace
    return await self._do_call(interaction, transformed_values)
           ^^^^^^^^^^^^^^^^^^^^^^^^^^^^^^^^^^^^^^^^^^^^^^^^^^^^
  File "C:\Users\Maria Rairez\AppData\Local\Programs\Python\Python311\Lib\site-packages\discord\app_commands\commands.py", line 876, in _do_call
    raise CommandInvokeError(self, e) from e
discord.app_commands.errors.CommandInvokeError: Command 'duel' raised an exception: HTTPException: 400 Bad Request (error code: 40060): Interaction has already been acknowledged.
Ignoring exception in on_ready
Traceback (most recent call last):
  File "C:\Users\Maria Rairez\AppData\Local\Programs\Python\Python311\Lib\site-packages\discord\client.py", line 481, in _run_event
    await coro(*args, **kwargs)
  File "c:\Users\Maria Rairez\Desktop\TCG\main.py", line 190, in on_ready
    bot.add_view(CatalogView([]))
  File "C:\Users\Maria Rairez\AppData\Local\Programs\Python\Python311\Lib\site-packages\discord\client.py", line 3182, in add_view
    raise ValueError('View is not persistent. Items need to have a custom_id set and View must have no timeout')
ValueError: View is not persistent. Items need to have a custom_id set and View must have no timeout
Ignoring exception in command 'duel'
Traceback (most recent call last):
  File "C:\Users\Maria Rairez\AppData\Local\Programs\Python\Python311\Lib\site-packages\discord\app_commands\commands.py", line 858, in _do_call
    return await self._callback(interaction, **params)  # type: ignore
           ^^^^^^^^^^^^^^^^^^^^^^^^^^^^^^^^^^^^^^^^^^^
  File "c:\Users\Maria Rairez\Desktop\TCG\main.py", line 1572, in duel
    await interaction.response.defer(ephemeral=False)
  File "C:\Users\Maria Rairez\AppData\Local\Programs\Python\Python311\Lib\site-packages\discord\interactions.py", line 844, in defer
    response = await adapter.create_interaction_response(
               ^^^^^^^^^^^^^^^^^^^^^^^^^^^^^^^^^^^^^^^^^^
  File "C:\Users\Maria Rairez\AppData\Local\Programs\Python\Python311\Lib\site-packages\discord\webhook\async_.py", line 226, in request
    raise HTTPException(response, data)
discord.errors.HTTPException: 400 Bad Request (error code: 40060): Interaction has already been acknowledged.

The above exception was the direct cause of the following exception:

Traceback (most recent call last):
  File "C:\Users\Maria Rairez\AppData\Local\Programs\Python\Python311\Lib\site-packages\discord\app_commands\tree.py", line 1310, in _call
    await command._invoke_with_namespace(interaction, namespace)
  File "C:\Users\Maria Rairez\AppData\Local\Programs\Python\Python311\Lib\site-packages\discord\app_commands\commands.py", line 883, in _invoke_with_namespace
    return await self._do_call(interaction, transformed_values)
           ^^^^^^^^^^^^^^^^^^^^^^^^^^^^^^^^^^^^^^^^^^^^^^^^^^^^
  File "C:\Users\Maria Rairez\AppData\Local\Programs\Python\Python311\Lib\site-packages\discord\app_commands\commands.py", line 876, in _do_call
    raise CommandInvokeError(self, e) from e
discord.app_commands.errors.CommandInvokeError: Command 'duel' raised an exception: HTTPException: 400 Bad Request (error code: 40060): Interaction has already been acknowledged.
Ignoring exception in command 'duel'
Traceback (most recent call last):
  File "C:\Users\Maria Rairez\AppData\Local\Programs\Python\Python311\Lib\site-packages\discord\app_commands\commands.py", line 858, in _do_call
    return await self._callback(interaction, **params)  # type: ignore
           ^^^^^^^^^^^^^^^^^^^^^^^^^^^^^^^^^^^^^^^^^^^
  File "c:\Users\Maria Rairez\Desktop\TCG\main.py", line 1572, in duel
    await interaction.response.defer(ephemeral=False)
  File "C:\Users\Maria Rairez\AppData\Local\Programs\Python\Python311\Lib\site-packages\discord\interactions.py", line 844, in defer
    response = await adapter.create_interaction_response(
               ^^^^^^^^^^^^^^^^^^^^^^^^^^^^^^^^^^^^^^^^^^
  File "C:\Users\Maria Rairez\AppData\Local\Programs\Python\Python311\Lib\site-packages\discord\webhook\async_.py", line 226, in request
    raise HTTPException(response, data)
discord.errors.HTTPException: 400 Bad Request (error code: 40060): Interaction has already been acknowledged.

The above exception was the direct cause of the following exception:

Traceback (most recent call last):
  File "C:\Users\Maria Rairez\AppData\Local\Programs\Python\Python311\Lib\site-packages\discord\app_commands\tree.py", line 1310, in _call
    await command._invoke_with_namespace(interaction, namespace)
  File "C:\Users\Maria Rairez\AppData\Local\Programs\Python\Python311\Lib\site-packages\discord\app_commands\commands.py", line 883, in _invoke_with_namespace
    return await self._do_call(interaction, transformed_values)
           ^^^^^^^^^^^^^^^^^^^^^^^^^^^^^^^^^^^^^^^^^^^^^^^^^^^^
  File "C:\Users\Maria Rairez\AppData\Local\Programs\Python\Python311\Lib\site-packages\discord\app_commands\commands.py", line 876, in _do_call
    raise CommandInvokeError(self, e) from e
discord.app_commands.errors.CommandInvokeError: Command 'duel' raised an exception: HTTPException: 400 Bad Request (error code: 40060): Interaction has already been acknowledged.
